(venv) D:\JRUFoundTracker>python main.py
Traceback (most recent call last):
  File "D:\JRUFoundTracker\venv\Lib\site-packages\sqlalchemy\engine\base.py", line 1964, in _exec_single_context
    self.dialect.do_execute(
    ~~~~~~~~~~~~~~~~~~~~~~~^
        cursor, str_statement, effective_parameters, context
        ^^^^^^^^^^^^^^^^^^^^^^^^^^^^^^^^^^^^^^^^^^^^^^^^^^^^
    )
    ^
  File "D:\JRUFoundTracker\venv\Lib\site-packages\sqlalchemy\engine\default.py", line 945, in do_execute
    cursor.execute(statement, parameters)
    ~~~~~~~~~~~~~~^^^^^^^^^^^^^^^^^^^^^^^
  File "D:\JRUFoundTracker\venv\Lib\site-packages\pymysql\cursors.py", line 153, in execute
    result = self._query(query)
  File "D:\JRUFoundTracker\venv\Lib\site-packages\pymysql\cursors.py", line 322, in _query
    conn.query(q)
    ~~~~~~~~~~^^^
  File "D:\JRUFoundTracker\venv\Lib\site-packages\pymysql\connections.py", line 563, in query
    self._affected_rows = self._read_query_result(unbuffered=unbuffered)
                          ~~~~~~~~~~~~~~~~~~~~~~~^^^^^^^^^^^^^^^^^^^^^^^
  File "D:\JRUFoundTracker\venv\Lib\site-packages\pymysql\connections.py", line 825, in _read_query_result
    result.read()
    ~~~~~~~~~~~^^
  File "D:\JRUFoundTracker\venv\Lib\site-packages\pymysql\connections.py", line 1199, in read
    first_packet = self.connection._read_packet()
  File "D:\JRUFoundTracker\venv\Lib\site-packages\pymysql\connections.py", line 775, in _read_packet
    packet.raise_for_error()
    ~~~~~~~~~~~~~~~~~~~~~~^^
  File "D:\JRUFoundTracker\venv\Lib\site-packages\pymysql\protocol.py", line 219, in raise_for_error
    err.raise_mysql_exception(self._data)
    ~~~~~~~~~~~~~~~~~~~~~~~~~^^^^^^^^^^^^
  File "D:\JRUFoundTracker\venv\Lib\site-packages\pymysql\err.py", line 150, in raise_mysql_exception
    raise errorclass(errno, errval)
pymysql.err.IntegrityError: (1062, "Duplicate entry 'Electronics' for key 'category.name'")

The above exception was the direct cause of the following exception:

Traceback (most recent call last):
  File "D:\JRUFoundTracker\main.py", line 1, in <module>
    from app import app
  File "D:\JRUFoundTracker\app.py", line 65, in <module>
    db.session.commit()
    ~~~~~~~~~~~~~~~~~^^
  File "D:\JRUFoundTracker\venv\Lib\site-packages\sqlalchemy\orm\scoping.py", line 599, in commit
    return self._proxied.commit()
           ~~~~~~~~~~~~~~~~~~~~^^
  File "D:\JRUFoundTracker\venv\Lib\site-packages\sqlalchemy\orm\session.py", line 2032, in commit
    trans.commit(_to_root=True)
    ~~~~~~~~~~~~^^^^^^^^^^^^^^^
  File "<string>", line 2, in commit
  File "D:\JRUFoundTracker\venv\Lib\site-packages\sqlalchemy\orm\state_changes.py", line 139, in _go
    ret_value = fn(self, *arg, **kw)
  File "D:\JRUFoundTracker\venv\Lib\site-packages\sqlalchemy\orm\session.py", line 1313, in commit
    self._prepare_impl()
    ~~~~~~~~~~~~~~~~~~^^
  File "<string>", line 2, in _prepare_impl
  File "D:\JRUFoundTracker\venv\Lib\site-packages\sqlalchemy\orm\state_changes.py", line 139, in _go
    ret_value = fn(self, *arg, **kw)
  File "D:\JRUFoundTracker\venv\Lib\site-packages\sqlalchemy\orm\session.py", line 1288, in _prepare_impl
    self.session.flush()
    ~~~~~~~~~~~~~~~~~~^^
  File "D:\JRUFoundTracker\venv\Lib\site-packages\sqlalchemy\orm\session.py", line 4353, in flush
    self._flush(objects)
    ~~~~~~~~~~~^^^^^^^^^
  File "D:\JRUFoundTracker\venv\Lib\site-packages\sqlalchemy\orm\session.py", line 4488, in _flush
    with util.safe_reraise():
         ~~~~~~~~~~~~~~~~~^^
  File "D:\JRUFoundTracker\venv\Lib\site-packages\sqlalchemy\util\langhelpers.py", line 146, in __exit__
    raise exc_value.with_traceback(exc_tb)
  File "D:\JRUFoundTracker\venv\Lib\site-packages\sqlalchemy\orm\session.py", line 4449, in _flush
    flush_context.execute()
    ~~~~~~~~~~~~~~~~~~~~~^^
  File "D:\JRUFoundTracker\venv\Lib\site-packages\sqlalchemy\orm\unitofwork.py", line 466, in execute
    rec.execute(self)
    ~~~~~~~~~~~^^^^^^
  File "D:\JRUFoundTracker\venv\Lib\site-packages\sqlalchemy\orm\unitofwork.py", line 642, in execute
    util.preloaded.orm_persistence.save_obj(
    ~~~~~~~~~~~~~~~~~~~~~~~~~~~~~~~~~~~~~~~^
        self.mapper,
        ^^^^^^^^^^^^
        uow.states_for_mapper_hierarchy(self.mapper, False, False),
        ^^^^^^^^^^^^^^^^^^^^^^^^^^^^^^^^^^^^^^^^^^^^^^^^^^^^^^^^^^^
        uow,
        ^^^^
    )
    ^
  File "D:\JRUFoundTracker\venv\Lib\site-packages\sqlalchemy\orm\persistence.py", line 93, in save_obj
    _emit_insert_statements(
    ~~~~~~~~~~~~~~~~~~~~~~~^
        base_mapper,
        ^^^^^^^^^^^^
    ...<3 lines>...
        insert,
        ^^^^^^^
    )
    ^
  File "D:\JRUFoundTracker\venv\Lib\site-packages\sqlalchemy\orm\persistence.py", line 1233, in _emit_insert_statements
    result = connection.execute(
        statement,
        params,
        execution_options=execution_options,
    )
  File "D:\JRUFoundTracker\venv\Lib\site-packages\sqlalchemy\engine\base.py", line 1416, in execute
    return meth(
        self,
        distilled_parameters,
        execution_options or NO_OPTIONS,
    )
  File "D:\JRUFoundTracker\venv\Lib\site-packages\sqlalchemy\sql\elements.py", line 523, in _execute_on_connection
    return connection._execute_clauseelement(
           ~~~~~~~~~~~~~~~~~~~~~~~~~~~~~~~~~^
        self, distilled_params, execution_options
        ^^^^^^^^^^^^^^^^^^^^^^^^^^^^^^^^^^^^^^^^^
    )
    ^
  File "D:\JRUFoundTracker\venv\Lib\site-packages\sqlalchemy\engine\base.py", line 1638, in _execute_clauseelement
    ret = self._execute_context(
        dialect,
    ...<8 lines>...
        cache_hit=cache_hit,
    )
  File "D:\JRUFoundTracker\venv\Lib\site-packages\sqlalchemy\engine\base.py", line 1843, in _execute_context
    return self._exec_single_context(
           ~~~~~~~~~~~~~~~~~~~~~~~~~^
        dialect, context, statement, parameters
        ^^^^^^^^^^^^^^^^^^^^^^^^^^^^^^^^^^^^^^^
    )
    ^
  File "D:\JRUFoundTracker\venv\Lib\site-packages\sqlalchemy\engine\base.py", line 1983, in _exec_single_context
    self._handle_dbapi_exception(
    ~~~~~~~~~~~~~~~~~~~~~~~~~~~~^
        e, str_statement, effective_parameters, cursor, context
        ^^^^^^^^^^^^^^^^^^^^^^^^^^^^^^^^^^^^^^^^^^^^^^^^^^^^^^^
    )
    ^
  File "D:\JRUFoundTracker\venv\Lib\site-packages\sqlalchemy\engine\base.py", line 2352, in _handle_dbapi_exception
    raise sqlalchemy_exception.with_traceback(exc_info[2]) from e
  File "D:\JRUFoundTracker\venv\Lib\site-packages\sqlalchemy\engine\base.py", line 1964, in _exec_single_context
    self.dialect.do_execute(
    ~~~~~~~~~~~~~~~~~~~~~~~^
        cursor, str_statement, effective_parameters, context
        ^^^^^^^^^^^^^^^^^^^^^^^^^^^^^^^^^^^^^^^^^^^^^^^^^^^^
    )
    ^
  File "D:\JRUFoundTracker\venv\Lib\site-packages\sqlalchemy\engine\default.py", line 945, in do_execute
    cursor.execute(statement, parameters)
    ~~~~~~~~~~~~~~^^^^^^^^^^^^^^^^^^^^^^^
  File "D:\JRUFoundTracker\venv\Lib\site-packages\pymysql\cursors.py", line 153, in execute
    result = self._query(query)
  File "D:\JRUFoundTracker\venv\Lib\site-packages\pymysql\cursors.py", line 322, in _query
    conn.query(q)
    ~~~~~~~~~~^^^
  File "D:\JRUFoundTracker\venv\Lib\site-packages\pymysql\connections.py", line 563, in query
    self._affected_rows = self._read_query_result(unbuffered=unbuffered)
                          ~~~~~~~~~~~~~~~~~~~~~~~^^^^^^^^^^^^^^^^^^^^^^^
  File "D:\JRUFoundTracker\venv\Lib\site-packages\pymysql\connections.py", line 825, in _read_query_result
    result.read()
    ~~~~~~~~~~~^^
  File "D:\JRUFoundTracker\venv\Lib\site-packages\pymysql\connections.py", line 1199, in read
    first_packet = self.connection._read_packet()
  File "D:\JRUFoundTracker\venv\Lib\site-packages\pymysql\connections.py", line 775, in _read_packet
    packet.raise_for_error()
    ~~~~~~~~~~~~~~~~~~~~~~^^
  File "D:\JRUFoundTracker\venv\Lib\site-packages\pymysql\protocol.py", line 219, in raise_for_error
    err.raise_mysql_exception(self._data)
    ~~~~~~~~~~~~~~~~~~~~~~~~~^^^^^^^^^^^^
  File "D:\JRUFoundTracker\venv\Lib\site-packages\pymysql\err.py", line 150, in raise_mysql_exception
    raise errorclass(errno, errval)
sqlalchemy.exc.IntegrityError: (pymysql.err.IntegrityError) (1062, "Duplicate entry 'Electronics' for key 'category.name'")
[SQL: INSERT INTO category (name, created_at) VALUES (%(name)s, %(created_at)s)]
[parameters: {'name': 'Electronics', 'created_at': datetime.datetime(2025, 4, 25, 10, 19, 33, 48880)}]
(Background on this error at: https://sqlalche.me/e/20/gkpj)